Absolutely, the interplay of multiple `try`, `catch`, and `finally` blocks can be confusing at first. Let's break it down:

### 1. **Multiple `catch` Blocks**

Multiple `catch` blocks allow you to handle different types of exceptions separately. Each `catch` block can handle a specific exception type, and they are executed sequentially from top to bottom. 

**Important:** Only one `catch` block will execute per `try` block, which will be the first one that matches the thrown exception type.

#### Example of Multiple `catch` Blocks

```java
try {
    // Code that may throw different types of exceptions
    int result = 10 / 0;               // This will throw ArithmeticException
    String text = null;
    System.out.println(text.length());  // This will throw NullPointerException
} catch (ArithmeticException e) {
    System.out.println("ArithmeticException caught: " + e.getMessage());
} catch (NullPointerException e) {
    System.out.println("NullPointerException caught: " + e.getMessage());
} catch (Exception e) {
    System.out.println("General exception caught: " + e.getMessage());
}
```

In this example:
- If an `ArithmeticException` is thrown, only the first `catch` block for `ArithmeticException` will execute.
- If a `NullPointerException` occurs, the `catch` block for `NullPointerException` will handle it.
- The final `catch (Exception e)` block acts as a general handler, catching any other `Exception` types not already handled.

### 2. **Multi-Catch Block**

Java 7 introduced a *multi-catch* feature, which allows you to catch multiple exception types in a single `catch` block. This is helpful when you have multiple exceptions that should be handled in the same way.

#### Syntax of Multi-Catch Block

```java
try {
    // Code that may throw multiple types of exceptions
} catch (IOException | SQLException e) {
    System.out.println("Caught IOException or SQLException: " + e.getMessage());
}
```

**Note:** In a multi-catch block, the exception variable (`e` in this case) is implicitly `final`, so you cannot modify it within the block.

### 3. **Nested `try-catch` Blocks**

A `try` block can contain another `try-catch` block within it, which is known as *nesting*. This is useful for handling exceptions at multiple levels, such as when a particular operation in a larger code block might require its own error handling.

#### Example of Nested `try-catch`

```java
try {
    System.out.println("Outer try block");
    
    try {
        int[] numbers = {1, 2, 3};
        System.out.println(numbers[5]); // Will throw ArrayIndexOutOfBoundsException
    } catch (ArrayIndexOutOfBoundsException e) {
        System.out.println("Inner catch block: ArrayIndexOutOfBoundsException caught");
    }
    
    int result = 10 / 0; // Will throw ArithmeticException
} catch (ArithmeticException e) {
    System.out.println("Outer catch block: ArithmeticException caught");
}
```

In this example:
- The inner `try-catch` handles `ArrayIndexOutOfBoundsException`.
- The outer `catch` block catches `ArithmeticException` from the outer `try` block.

### 4. **try-finally (Without `catch`)**

Sometimes, you may not need a `catch` block if you just want to ensure certain code always runs, regardless of whether an exception occurs. In this case, you can use a `try-finally` block without `catch`.

#### Example of `try-finally`

```java
try {
    System.out.println("Executing try block");
    int result = 10 / 0;  // This will throw ArithmeticException
} finally {
    System.out.println("Finally block always executes");
}
```

Here:
- The `finally` block will execute even though an `ArithmeticException` occurs, ensuring that any necessary cleanup (like closing a file or database connection) can still happen.

### 5. **`try` with Multiple `finally` Blocks**

Only one `finally` block can be associated with a single `try` block. However, if you have nested `try` blocks, each `try` can have its own `finally`. Each `finally` block executes after its corresponding `try` or `catch` block completes.

#### Example of Nested `try-finally`

```java
try {
    System.out.println("Outer try block");
    try {
        System.out.println("Inner try block");
        int result = 10 / 0; // Throws ArithmeticException
    } finally {
        System.out.println("Inner finally block executes");
    }
} catch (ArithmeticException e) {
    System.out.println("Outer catch block: ArithmeticException caught");
} finally {
    System.out.println("Outer finally block executes");
}
```

In this example:
- When `ArithmeticException` is thrown in the inner `try` block, the inner `finally` block executes, followed by the outer `catch` block, and then the outer `finally` block.

### 6. **Order of Execution in try-catch-finally**

The order in which `try`, `catch`, and `finally` blocks execute is crucial to understanding their behavior:

1. The `try` block executes first.
2. If an exception occurs, the control goes to the first matching `catch` block.
3. After the `catch` block executes, the `finally` block (if present) always executes.
4. If there’s no exception, the `try` block completes, and then the `finally` block executes.

#### Example to Illustrate Order of Execution

```java
try {
    System.out.println("Try block executed");
    int result = 10 / 0; // This will throw ArithmeticException
} catch (ArithmeticException e) {
    System.out.println("Catch block executed for ArithmeticException");
} finally {
    System.out.println("Finally block executed");
}
```

Output:
```
Try block executed
Catch block executed for ArithmeticException
Finally block executed
```

In summary:
- **Multiple `catch` blocks** help handle different types of exceptions specifically.
- **Multi-catch** syntax (`catch (Exception1 | Exception2 e)`) consolidates common handling of multiple exceptions.
- **Nested `try-catch`** helps manage exceptions at different levels of code.
- **`finally` always executes** and is often used for cleanup.
- **Order of execution** in `try-catch-finally` is straightforward: `try` → `catch` (if an exception occurs) → `finally`.

Understanding these nuances helps you control program flow during exceptions and makes your code more resilient.